<?xml version="1.0"?>
<robot name="controlled_humanoid">

  <!-- Material definitions -->
  <material name="Blue">
    <color rgba="0.0 0.0 1.0 1.0"/>
  </material>
  <material name="Red">
    <color rgba="1.0 0.0 0.0 1.0"/>
  </material>
  <material name="Green">
    <color rgba="0.0 1.0 0.0 1.0"/>
  </material>
  <material name="White">
    <color rgba="1.0 1.0 1.0 1.0"/>
  </material>
  <material name="Black">
    <color rgba="0.1 0.1 0.1 1.0"/>
  </material>

  <!-- Base link -->
  <link name="base_link">
    <visual>
      <geometry>
        <box size="0.3 0.2 0.4"/>
      </geometry>
      <material name="Blue"/>
    </visual>
    <collision>
      <geometry>
        <box size="0.3 0.2 0.4"/>
      </geometry>
    </collision>
    <inertial>
      <mass value="10.0"/>
      <inertia ixx="0.1" ixy="0.0" ixz="0.0" iyy="0.2" iyz="0.0" izz="0.1"/>
    </inertial>
  </link>

  <!-- Torso -->
  <joint name="torso_joint" type="fixed">
    <parent link="base_link"/>
    <child link="torso"/>
    <origin xyz="0 0 0.2"/>
  </joint>

  <link name="torso">
    <visual>
      <geometry>
        <box size="0.25 0.18 0.5"/>
      </geometry>
      <material name="White"/>
    </visual>
    <collision>
      <geometry>
        <box size="0.25 0.18 0.5"/>
      </geometry>
    </collision>
    <inertial>
      <mass value="8.0"/>
      <inertia ixx="0.2" ixy="0.0" ixz="0.0" iyy="0.3" iyz="0.0" izz="0.2"/>
    </inertial>
  </link>

  <!-- Head -->
  <joint name="neck_joint" type="revolute">
    <parent link="torso"/>
    <child link="head"/>
    <origin xyz="0 0 0.35"/>
    <axis xyz="0 1 0"/>
    <limit lower="-0.5" upper="0.5" effort="10.0" velocity="2.0"/>
  </joint>

  <link name="head">
    <visual>
      <geometry>
        <sphere radius="0.1"/>
      </geometry>
      <material name="White"/>
    </visual>
    <collision>
      <geometry>
        <sphere radius="0.1"/>
      </geometry>
    </collision>
    <inertial>
      <mass value="1.0"/>
      <inertia ixx="0.01" ixy="0.0" ixz="0.0" iyy="0.01" iyz="0.0" izz="0.01"/>
    </inertial>
  </link>

  <!-- Left Shoulder -->
  <joint name="left_shoulder_joint" type="revolute">
    <parent link="torso"/>
    <child link="left_upper_arm"/>
    <origin xyz="0.15 0 0.2"/>
    <axis xyz="0 1 0"/>
    <limit lower="-1.57" upper="1.57" effort="20.0" velocity="2.0"/>
  </joint>

  <link name="left_upper_arm">
    <visual>
      <geometry>
        <cylinder length="0.3" radius="0.05"/>
      </geometry>
      <material name="Red"/>
    </visual>
    <collision>
      <geometry>
        <cylinder length="0.3" radius="0.05"/>
      </geometry>
    </collision>
    <inertial>
      <mass value="1.5"/>
      <inertia ixx="0.02" ixy="0.0" ixz="0.0" iyy="0.02" iyz="0.0" izz="0.001"/>
    </inertial>
  </link>

  <!-- Left Elbow -->
  <joint name="left_elbow_joint" type="revolute">
    <parent link="left_upper_arm"/>
    <child link="left_lower_arm"/>
    <origin xyz="0 0 -0.15"/>
    <axis xyz="1 0 0"/>
    <limit lower="-1.57" upper="1.57" effort="15.0" velocity="2.0"/>
  </joint>

  <link name="left_lower_arm">
    <visual>
      <geometry>
        <cylinder length="0.25" radius="0.04"/>
      </geometry>
      <material name="Red"/>
    </visual>
    <collision>
      <geometry>
        <cylinder length="0.25" radius="0.04"/>
      </geometry>
    </collision>
    <inertial>
      <mass value="1.0"/>
      <inertia ixx="0.01" ixy="0.0" ixz="0.0" iyy="0.01" iyz="0.0" izz="0.0008"/>
    </inertial>
  </link>

  <!-- Right Shoulder -->
  <joint name="right_shoulder_joint" type="revolute">
    <parent link="torso"/>
    <child link="right_upper_arm"/>
    <origin xyz="-0.15 0 0.2"/>
    <axis xyz="0 1 0"/>
    <limit lower="-1.57" upper="1.57" effort="20.0" velocity="2.0"/>
  </joint>

  <link name="right_upper_arm">
    <visual>
      <geometry>
        <cylinder length="0.3" radius="0.05"/>
      </geometry>
      <material name="Green"/>
    </visual>
    <collision>
      <geometry>
        <cylinder length="0.3" radius="0.05"/>
      </geometry>
    </collision>
    <inertial>
      <mass value="1.5"/>
      <inertia ixx="0.02" ixy="0.0" ixz="0.0" iyy="0.02" iyz="0.0" izz="0.001"/>
    </inertial>
  </link>

  <!-- Right Elbow -->
  <joint name="right_elbow_joint" type="revolute">
    <parent link="right_upper_arm"/>
    <child link="right_lower_arm"/>
    <origin xyz="0 0 -0.15"/>
    <axis xyz="1 0 0"/>
    <limit lower="-1.57" upper="1.57" effort="15.0" velocity="2.0"/>
  </joint>

  <link name="right_lower_arm">
    <visual>
      <geometry>
        <cylinder length="0.25" radius="0.04"/>
      </geometry>
      <material name="Green"/>
    </visual>
    <collision>
      <geometry>
        <cylinder length="0.25" radius="0.04"/>
      </geometry>
    </collision>
    <inertial>
      <mass value="1.0"/>
      <inertia ixx="0.01" ixy="0.0" ixz="0.0" iyy="0.01" iyz="0.0" izz="0.0008"/>
    </inertial>
  </link>

  <!-- Left Hip -->
  <joint name="left_hip_joint" type="revolute">
    <parent link="base_link"/>
    <child link="left_thigh"/>
    <origin xyz="0.08 -0.08 -0.2"/>
    <axis xyz="0 1 0"/>
    <limit lower="-1.57" upper="1.57" effort="30.0" velocity="2.0"/>
  </joint>

  <link name="left_thigh">
    <visual>
      <geometry>
        <cylinder length="0.4" radius="0.06"/>
      </geometry>
      <material name="Black"/>
    </visual>
    <collision>
      <geometry>
        <cylinder length="0.4" radius="0.06"/>
      </geometry>
    </collision>
    <inertial>
      <mass value="2.0"/>
      <inertia ixx="0.05" ixy="0.0" ixz="0.0" iyy="0.05" iyz="0.0" izz="0.001"/>
    </inertial>
  </link>

  <!-- Left Knee -->
  <joint name="left_knee_joint" type="revolute">
    <parent link="left_thigh"/>
    <child link="left_shin"/>
    <origin xyz="0 0 -0.2"/>
    <axis xyz="1 0 0"/>
    <limit lower="-1.57" upper="0.0" effort="30.0" velocity="2.0"/>
  </joint>

  <link name="left_shin">
    <visual>
      <geometry>
        <cylinder length="0.35" radius="0.05"/>
      </geometry>
      <material name="Black"/>
    </visual>
    <collision>
      <geometry>
        <cylinder length="0.35" radius="0.05"/>
      </geometry>
    </collision>
    <inertial>
      <mass value="1.5"/>
      <inertia ixx="0.03" ixy="0.0" ixz="0.0" iyy="0.03" iyz="0.0" izz="0.001"/>
    </inertial>
  </link>

  <!-- Left Ankle -->
  <joint name="left_ankle_joint" type="revolute">
    <parent link="left_shin"/>
    <child link="left_foot"/>
    <origin xyz="0 0 -0.175"/>
    <axis xyz="1 0 0"/>
    <limit lower="-0.5" upper="0.5" effort="20.0" velocity="1.0"/>
  </joint>

  <link name="left_foot">
    <visual>
      <geometry>
        <box size="0.15 0.08 0.05"/>
      </geometry>
      <material name="Black"/>
    </visual>
    <collision>
      <geometry>
        <box size="0.15 0.08 0.05"/>
      </geometry>
    </collision>
    <inertial>
      <mass value="0.5"/>
      <inertia ixx="0.001" ixy="0.0" ixz="0.0" iyy="0.001" iyz="0.0" izz="0.001"/>
    </inertial>
  </link>

  <!-- Right Hip -->
  <joint name="right_hip_joint" type="revolute">
    <parent link="base_link"/>
    <child link="right_thigh"/>
    <origin xyz="0.08 0.08 -0.2"/>
    <axis xyz="0 1 0"/>
    <limit lower="-1.57" upper="1.57" effort="30.0" velocity="2.0"/>
  </joint>

  <link name="right_thigh">
    <visual>
      <geometry>
        <cylinder length="0.4" radius="0.06"/>
      </geometry>
      <material name="Black"/>
    </visual>
    <collision>
      <geometry>
        <cylinder length="0.4" radius="0.06"/>
      </geometry>
    </collision>
    <inertial>
      <mass value="2.0"/>
      <inertia ixx="0.05" ixy="0.0" ixz="0.0" iyy="0.05" iyz="0.0" izz="0.001"/>
    </inertial>
  </link>

  <!-- Right Knee -->
  <joint name="right_knee_joint" type="revolute">
    <parent link="right_thigh"/>
    <child link="right_shin"/>
    <origin xyz="0 0 -0.2"/>
    <axis xyz="1 0 0"/>
    <limit lower="-1.57" upper="0.0" effort="30.0" velocity="2.0"/>
  </joint>

  <link name="right_shin">
    <visual>
      <geometry>
        <cylinder length="0.35" radius="0.05"/>
      </geometry>
      <material name="Black"/>
    </visual>
    <collision>
      <geometry>
        <cylinder length="0.35" radius="0.05"/>
      </geometry>
    </collision>
    <inertial>
      <mass value="1.5"/>
      <inertia ixx="0.03" ixy="0.0" ixz="0.0" iyy="0.03" iyz="0.0" izz="0.001"/>
    </inertial>
  </link>

  <!-- Right Ankle -->
  <joint name="right_ankle_joint" type="revolute">
    <parent link="right_shin"/>
    <child link="right_foot"/>
    <origin xyz="0 0 -0.175"/>
    <axis xyz="1 0 0"/>
    <limit lower="-0.5" upper="0.5" effort="20.0" velocity="1.0"/>
  </joint>

  <link name="right_foot">
    <visual>
      <geometry>
        <box size="0.15 0.08 0.05"/>
      </geometry>
      <material name="Black"/>
    </visual>
    <collision>
      <geometry>
        <box size="0.15 0.08 0.05"/>
      </geometry>
    </collision>
    <inertial>
      <mass value="0.5"/>
      <inertia ixx="0.001" ixy="0.0" ixz="0.0" iyy="0.001" iyz="0.0" izz="0.001"/>
    </inertial>
  </link>

  <!-- Sensors -->
  <!-- IMU sensor in the torso -->
  <sensor name="imu_sensor" type="imu">
    <origin xyz="0 0 0.1" rpy="0 0 0"/>
    <parent link="torso"/>
    <always_on>1</always_on>
    <update_rate>100</update_rate>
  </sensor>

  <!-- Camera in the head -->
  <sensor name="camera_sensor" type="camera">
    <origin xyz="0.05 0 0.05" rpy="0 0 0"/>
    <parent link="head"/>
    <always_on>1</always_on>
    <update_rate>30</update_rate>
  </sensor>

</robot>